<!-- Author + Copyright (C) Aravind Rajeswaran, rajeswaran.aravind@gmail.com.
See LICENSE file for legal notices. LICENSE must be kept together with this file.
modified by klowrey
modified by Sasha Abramowitz
-->
<mujoco model="PointMass">
    <compiler inertiafromgeom="true" angle="radian" />
    <default>
        <joint armature="0.01" damping="0.1" limited="true"/>
        <geom contype="0" friction="1 0.1 0.1" rgba="0.7 0.7 0 1"/>
        <motor ctrllimited="true" ctrlrange="-1.0 1.0" />
    </default>
    <option gravity="0 0 0" timestep="0.02"/>

    <asset>
        <texture type="skybox" builtin="gradient" rgb1=".1 .12 .15" rgb2="0 0 0" width="100" height="100"/>
        <texture builtin="flat" height="100" name="grayplane" rgb1="0.4 0.4 0.4" rgb2=".1 0.15 0.2" type="2d" width="100"/>
        <texture builtin="checker" height="100" name="texplane" rgb1="0 0 0" rgb2="0.8 0.8 0.8" type="2d" width="100"/>
        <material name="MatPlane" reflectance="0.5" shininess="1" specular="1" texrepeat="60 60" texture="texplane"/>
    </asset>

    <worldbody>
        <!-- Arena -->
        <light cutoff="100" diffuse="1 1 1" dir="-0 0 -1.3" directional="true" exponent="1" pos="0 0 1.3" specular=".1 .1 .1"/>
        <geom conaffinity="1" condim="3" material="MatPlane" name="floor" pos="0 0 0" rgba="0.8 0.9 0.8 1" size="40 40 40" type="plane"/>

        <!-- Agent -->
        <body name="agent" pos="0 0 .05">
            <joint axis="1 0 0" name="agent_x" pos="0 0 0" range="-20 20" stiffness="0" type="slide"/>
            <joint axis="0 1 0" name="agent_y" pos="0 0 0" range="-20 20" stiffness="0" type="slide"/>
            <geom conaffinity="1" contype="1" name="agent" pos="0 0 0.25" rgba="1 1 0.6 1" size=".25" type="sphere"/>
        </body>

        <!-- Target -->
        <!-- <site name="target" pos="1.0 0 .05" rgba="0.6 0.2 0.2 0.2" size=".07" type="sphere" /> -->
        <!-- <body name="target" pos="1 0 .05">
            <joint axis="1 0 0" name="target_x" pos="0 0 0" range="-1.4 1.4" ref="1" stiffness="0" type="slide"/>
            <joint axis="0 1 0" name="target_y" pos="0 0 0" range="-1.4 1.4" stiffness="0" type="slide"/>
            <geom conaffinity="0" contype="0" name="target" pos="0 0 0" rgba="0.6 0.2 0.2 0.2" size=".07" type="sphere"/>
        </body> -->

        <geom name="recomend_geom" pos="4 4 -1" size="0.25" type="sphere" material="" contype="2" conaffinity="2" condim="6" rgba="0.9 0 1 1"/>
        <geom name="target_geom" pos="5 5 -1" size="0.25" type="sphere" material="" contype="2" conaffinity="2" condim="6" rgba="0.4 0.4 1 1" />
        <geom name="goal" pos="0 16 0" size="0.25" type="sphere" material="" contype="2" conaffinity="2" condim="6" rgba="1 0 0 1" />

    </worldbody>

    <actuator>
        <motor gear="8.0" joint="agent_x"/>
        <motor gear="8.0" joint="agent_y"/>
    </actuator>

</mujoco>